[2023-12-12 01:51:08,568] INFO _log() L187   * Restarting with stat - call_trace=C:\Python311\Lib\site-packages\werkzeug\_internal.py L187 
[2023-12-12 01:51:10,349] ERROR insert() L140  Erro inesperado ao inserir doador: 'Donator' object has no attribute 'dict' - call_trace=C:\Users\fmsco\OneDrive\Área de Trabalho\Códigos Pós\sprint 2\red_flow\backend\app.py L140 
Traceback (most recent call last):
  File "C:\Users\fmsco\OneDrive\Área de Trabalho\Códigos Pós\sprint 2\red_flow\backend\app.py", line 123, in insert
    form_data = DonatorSchema(**doador.dict())
                                ^^^^^^^^^^^
AttributeError: 'Donator' object has no attribute 'dict'
[2023-12-12 01:51:10,353] ERROR log_exception() L1414 Exception on /swagger/novodoador [POST] - call_trace=C:\Python311\Lib\site-packages\flask\app.py L1414
Traceback (most recent call last):
  File "C:\Python311\Lib\site-packages\flask\app.py", line 2190, in wsgi_app
    response = self.full_dispatch_request()
               ^^^^^^^^^^^^^^^^^^^^^^^^^^^^
  File "C:\Python311\Lib\site-packages\flask\app.py", line 1487, in full_dispatch_request
    return self.finalize_request(rv)
           ^^^^^^^^^^^^^^^^^^^^^^^^^
  File "C:\Python311\Lib\site-packages\flask\app.py", line 1506, in finalize_request
    response = self.make_response(rv)
               ^^^^^^^^^^^^^^^^^^^^^^
  File "C:\Python311\Lib\site-packages\flask\app.py", line 1820, in make_response
    rv = self.json.response(rv)
         ^^^^^^^^^^^^^^^^^^^^^^
  File "C:\Python311\Lib\site-packages\flask\json\provider.py", line 215, in response
    f"{self.dumps(obj, **dump_args)}\n", mimetype=self.mimetype
       ^^^^^^^^^^^^^^^^^^^^^^^^^^^^
  File "C:\Python311\Lib\site-packages\flask\json\provider.py", line 180, in dumps
    return json.dumps(obj, **kwargs)
           ^^^^^^^^^^^^^^^^^^^^^^^^^
  File "C:\Python311\Lib\json\__init__.py", line 238, in dumps
    **kw).encode(obj)
          ^^^^^^^^^^^
  File "C:\Python311\Lib\json\encoder.py", line 200, in encode
    chunks = self.iterencode(o, _one_shot=True)
             ^^^^^^^^^^^^^^^^^^^^^^^^^^^^^^^^^^
  File "C:\Python311\Lib\json\encoder.py", line 258, in iterencode
    return _iterencode(o, 0)
           ^^^^^^^^^^^^^^^^^
  File "C:\Python311\Lib\site-packages\flask\json\provider.py", line 120, in _default
    raise TypeError(f"Object of type {type(o).__name__} is not JSON serializable")
TypeError: Object of type AttributeError is not JSON serializable
[2023-12-12 01:51:10,358] INFO _log() L187  127.0.0.1 - - [12/Dec/2023 01:51:10] "[35m[1mPOST /swagger/novodoador HTTP/1.1[0m" 500 - - call_trace=C:\Python311\Lib\site-packages\werkzeug\_internal.py L187 
[2023-12-12 01:52:40,766] INFO _log() L187   * Detected change in 'C:\\Users\\fmsco\\OneDrive\\Área de Trabalho\\Códigos Pós\\sprint 2\\red_flow\\backend\\app.py', reloading - call_trace=C:\Python311\Lib\site-packages\werkzeug\_internal.py L187 
[2023-12-12 01:52:40,867] INFO _log() L187   * Restarting with stat - call_trace=C:\Python311\Lib\site-packages\werkzeug\_internal.py L187 
[2023-12-12 01:52:55,212] INFO _log() L187   * Detected change in 'C:\\Users\\fmsco\\OneDrive\\Área de Trabalho\\Códigos Pós\\sprint 2\\red_flow\\backend\\app.py', reloading - call_trace=C:\Python311\Lib\site-packages\werkzeug\_internal.py L187 
[2023-12-12 01:52:55,262] INFO _log() L187   * Restarting with stat - call_trace=C:\Python311\Lib\site-packages\werkzeug\_internal.py L187 
[2023-12-12 01:54:02,246] INFO _log() L187   * Detected change in 'C:\\Users\\fmsco\\OneDrive\\Área de Trabalho\\Códigos Pós\\sprint 2\\red_flow\\backend\\schemas\\donator_schema.py', reloading - call_trace=C:\Python311\Lib\site-packages\werkzeug\_internal.py L187 
[2023-12-12 01:54:02,315] INFO _log() L187   * Restarting with stat - call_trace=C:\Python311\Lib\site-packages\werkzeug\_internal.py L187 
[2023-12-12 01:54:06,641] INFO _log() L187   * Detected change in 'C:\\Users\\fmsco\\OneDrive\\Área de Trabalho\\Códigos Pós\\sprint 2\\red_flow\\backend\\schemas\\donator_schema.py', reloading - call_trace=C:\Python311\Lib\site-packages\werkzeug\_internal.py L187 
[2023-12-12 01:54:06,672] INFO _log() L187   * Restarting with stat - call_trace=C:\Python311\Lib\site-packages\werkzeug\_internal.py L187 
[2023-12-12 01:54:35,472] ERROR insert() L138  Erro inesperado ao inserir doador: 'Donator' object has no attribute 'dict' - call_trace=C:\Users\fmsco\OneDrive\Área de Trabalho\Códigos Pós\sprint 2\red_flow\backend\app.py L138 
Traceback (most recent call last):
  File "C:\Users\fmsco\OneDrive\Área de Trabalho\Códigos Pós\sprint 2\red_flow\backend\app.py", line 121, in insert
    form_data = DonatorSchema(**doador.dict())
                                ^^^^^^^^^^^
AttributeError: 'Donator' object has no attribute 'dict'
[2023-12-12 01:54:35,473] ERROR log_exception() L1414 Exception on /swagger/novodoador [POST] - call_trace=C:\Python311\Lib\site-packages\flask\app.py L1414
Traceback (most recent call last):
  File "C:\Python311\Lib\site-packages\flask\app.py", line 2190, in wsgi_app
    response = self.full_dispatch_request()
               ^^^^^^^^^^^^^^^^^^^^^^^^^^^^
  File "C:\Python311\Lib\site-packages\flask\app.py", line 1487, in full_dispatch_request
    return self.finalize_request(rv)
           ^^^^^^^^^^^^^^^^^^^^^^^^^
  File "C:\Python311\Lib\site-packages\flask\app.py", line 1506, in finalize_request
    response = self.make_response(rv)
               ^^^^^^^^^^^^^^^^^^^^^^
  File "C:\Python311\Lib\site-packages\flask\app.py", line 1820, in make_response
    rv = self.json.response(rv)
         ^^^^^^^^^^^^^^^^^^^^^^
  File "C:\Python311\Lib\site-packages\flask\json\provider.py", line 215, in response
    f"{self.dumps(obj, **dump_args)}\n", mimetype=self.mimetype
       ^^^^^^^^^^^^^^^^^^^^^^^^^^^^
  File "C:\Python311\Lib\site-packages\flask\json\provider.py", line 180, in dumps
    return json.dumps(obj, **kwargs)
           ^^^^^^^^^^^^^^^^^^^^^^^^^
  File "C:\Python311\Lib\json\__init__.py", line 238, in dumps
    **kw).encode(obj)
          ^^^^^^^^^^^
  File "C:\Python311\Lib\json\encoder.py", line 200, in encode
    chunks = self.iterencode(o, _one_shot=True)
             ^^^^^^^^^^^^^^^^^^^^^^^^^^^^^^^^^^
  File "C:\Python311\Lib\json\encoder.py", line 258, in iterencode
    return _iterencode(o, 0)
           ^^^^^^^^^^^^^^^^^
  File "C:\Python311\Lib\site-packages\flask\json\provider.py", line 120, in _default
    raise TypeError(f"Object of type {type(o).__name__} is not JSON serializable")
TypeError: Object of type AttributeError is not JSON serializable
[2023-12-12 01:54:35,477] INFO _log() L187  127.0.0.1 - - [12/Dec/2023 01:54:35] "[35m[1mPOST /swagger/novodoador HTTP/1.1[0m" 500 - - call_trace=C:\Python311\Lib\site-packages\werkzeug\_internal.py L187 
[2023-12-12 01:54:46,224] ERROR insert() L138  Erro inesperado ao inserir doador: 'Donator' object has no attribute 'dict' - call_trace=C:\Users\fmsco\OneDrive\Área de Trabalho\Códigos Pós\sprint 2\red_flow\backend\app.py L138 
Traceback (most recent call last):
  File "C:\Users\fmsco\OneDrive\Área de Trabalho\Códigos Pós\sprint 2\red_flow\backend\app.py", line 121, in insert
    form_data = DonatorSchema(**doador.dict())
                                ^^^^^^^^^^^
AttributeError: 'Donator' object has no attribute 'dict'
[2023-12-12 01:54:46,225] ERROR log_exception() L1414 Exception on /swagger/novodoador [POST] - call_trace=C:\Python311\Lib\site-packages\flask\app.py L1414
Traceback (most recent call last):
  File "C:\Python311\Lib\site-packages\flask\app.py", line 2190, in wsgi_app
    response = self.full_dispatch_request()
               ^^^^^^^^^^^^^^^^^^^^^^^^^^^^
  File "C:\Python311\Lib\site-packages\flask\app.py", line 1487, in full_dispatch_request
    return self.finalize_request(rv)
           ^^^^^^^^^^^^^^^^^^^^^^^^^
  File "C:\Python311\Lib\site-packages\flask\app.py", line 1506, in finalize_request
    response = self.make_response(rv)
               ^^^^^^^^^^^^^^^^^^^^^^
  File "C:\Python311\Lib\site-packages\flask\app.py", line 1820, in make_response
    rv = self.json.response(rv)
         ^^^^^^^^^^^^^^^^^^^^^^
  File "C:\Python311\Lib\site-packages\flask\json\provider.py", line 215, in response
    f"{self.dumps(obj, **dump_args)}\n", mimetype=self.mimetype
       ^^^^^^^^^^^^^^^^^^^^^^^^^^^^
  File "C:\Python311\Lib\site-packages\flask\json\provider.py", line 180, in dumps
    return json.dumps(obj, **kwargs)
           ^^^^^^^^^^^^^^^^^^^^^^^^^
  File "C:\Python311\Lib\json\__init__.py", line 238, in dumps
    **kw).encode(obj)
          ^^^^^^^^^^^
  File "C:\Python311\Lib\json\encoder.py", line 200, in encode
    chunks = self.iterencode(o, _one_shot=True)
             ^^^^^^^^^^^^^^^^^^^^^^^^^^^^^^^^^^
  File "C:\Python311\Lib\json\encoder.py", line 258, in iterencode
    return _iterencode(o, 0)
           ^^^^^^^^^^^^^^^^^
  File "C:\Python311\Lib\site-packages\flask\json\provider.py", line 120, in _default
    raise TypeError(f"Object of type {type(o).__name__} is not JSON serializable")
TypeError: Object of type AttributeError is not JSON serializable
[2023-12-12 01:54:46,230] INFO _log() L187  127.0.0.1 - - [12/Dec/2023 01:54:46] "[35m[1mPOST /swagger/novodoador HTTP/1.1[0m" 500 - - call_trace=C:\Python311\Lib\site-packages\werkzeug\_internal.py L187 
[2023-12-12 01:55:14,909] INFO _log() L187   * Detected change in 'C:\\Users\\fmsco\\OneDrive\\Área de Trabalho\\Códigos Pós\\sprint 2\\red_flow\\backend\\app.py', reloading - call_trace=C:\Python311\Lib\site-packages\werkzeug\_internal.py L187 
[2023-12-12 01:55:15,022] INFO _log() L187   * Restarting with stat - call_trace=C:\Python311\Lib\site-packages\werkzeug\_internal.py L187 
[2023-12-12 01:55:21,293] INFO _log() L187   * Restarting with stat - call_trace=C:\Python311\Lib\site-packages\werkzeug\_internal.py L187 
