[2023-12-12 01:45:06,046] INFO _log() L187   * Restarting with stat - call_trace=C:\Python311\Lib\site-packages\werkzeug\_internal.py L187 
[2023-12-12 01:45:09,416] INFO _log() L187   * Detected change in 'C:\\Users\\fmsco\\OneDrive\\Área de Trabalho\\Códigos Pós\\sprint 2\\red_flow\\backend\\app.py', reloading - call_trace=C:\Python311\Lib\site-packages\werkzeug\_internal.py L187 
[2023-12-12 01:45:09,470] INFO _log() L187   * Restarting with stat - call_trace=C:\Python311\Lib\site-packages\werkzeug\_internal.py L187 
[2023-12-12 01:45:15,364] INFO _log() L187   * Detected change in 'C:\\Users\\fmsco\\OneDrive\\Área de Trabalho\\Códigos Pós\\sprint 2\\red_flow\\backend\\app.py', reloading - call_trace=C:\Python311\Lib\site-packages\werkzeug\_internal.py L187 
[2023-12-12 01:45:15,411] INFO _log() L187   * Restarting with stat - call_trace=C:\Python311\Lib\site-packages\werkzeug\_internal.py L187 
[2023-12-12 01:45:18,833] ERROR log_exception() L1414 Exception on /swagger/novodoador [POST] - call_trace=C:\Python311\Lib\site-packages\flask\app.py L1414
Traceback (most recent call last):
  File "C:\Python311\Lib\site-packages\flask\app.py", line 2190, in wsgi_app
    response = self.full_dispatch_request()
               ^^^^^^^^^^^^^^^^^^^^^^^^^^^^
  File "C:\Python311\Lib\site-packages\flask\app.py", line 1486, in full_dispatch_request
    rv = self.handle_user_exception(e)
         ^^^^^^^^^^^^^^^^^^^^^^^^^^^^^
  File "C:\Python311\Lib\site-packages\flask_cors\extension.py", line 176, in wrapped_function
    return cors_after_request(app.make_response(f(*args, **kwargs)))
                                                ^^^^^^^^^^^^^^^^^^
  File "C:\Python311\Lib\site-packages\flask\app.py", line 1484, in full_dispatch_request
    rv = self.dispatch_request()
         ^^^^^^^^^^^^^^^^^^^^^^^
  File "C:\Python311\Lib\site-packages\flask\app.py", line 1469, in dispatch_request
    return self.ensure_sync(self.view_functions[rule.endpoint])(**view_args)
           ^^^^^^^^^^^^^^^^^^^^^^^^^^^^^^^^^^^^^^^^^^^^^^^^^^^^^^^^^^^^^^^^^
  File "C:\Python311\Lib\site-packages\flask_openapi3\scaffold.py", line 127, in view_func
    response = func(**func_kwargs)
               ^^^^^^^^^^^^^^^^^^^
  File "C:\Users\fmsco\OneDrive\Área de Trabalho\Códigos Pós\sprint 2\red_flow\backend\app.py", line 89, in insert
    new_form = form_dict.outcome.pop(form_dict.outcome, None)
               ^^^^^^^^^^^^^^^^^
AttributeError: 'dict' object has no attribute 'outcome'
[2023-12-12 01:45:18,839] INFO _log() L187  127.0.0.1 - - [12/Dec/2023 01:45:18] "[35m[1mPOST /swagger/novodoador HTTP/1.1[0m" 500 - - call_trace=C:\Python311\Lib\site-packages\werkzeug\_internal.py L187 
[2023-12-12 01:45:28,588] INFO _log() L187   * Detected change in 'C:\\Users\\fmsco\\OneDrive\\Área de Trabalho\\Códigos Pós\\sprint 2\\red_flow\\backend\\app.py', reloading - call_trace=C:\Python311\Lib\site-packages\werkzeug\_internal.py L187 
[2023-12-12 01:45:28,656] INFO _log() L187   * Restarting with stat - call_trace=C:\Python311\Lib\site-packages\werkzeug\_internal.py L187 
[2023-12-12 01:45:29,676] INFO _log() L187   * Detected change in 'C:\\Users\\fmsco\\OneDrive\\Área de Trabalho\\Códigos Pós\\sprint 2\\red_flow\\backend\\app.py', reloading - call_trace=C:\Python311\Lib\site-packages\werkzeug\_internal.py L187 
[2023-12-12 01:45:29,724] INFO _log() L187   * Restarting with stat - call_trace=C:\Python311\Lib\site-packages\werkzeug\_internal.py L187 
[2023-12-12 01:45:34,248] INFO _log() L187   * Detected change in 'C:\\Users\\fmsco\\OneDrive\\Área de Trabalho\\Códigos Pós\\sprint 2\\red_flow\\backend\\app.py', reloading - call_trace=C:\Python311\Lib\site-packages\werkzeug\_internal.py L187 
[2023-12-12 01:45:34,299] INFO _log() L187   * Restarting with stat - call_trace=C:\Python311\Lib\site-packages\werkzeug\_internal.py L187 
[2023-12-12 01:45:37,526] INFO _log() L187   * Restarting with stat - call_trace=C:\Python311\Lib\site-packages\werkzeug\_internal.py L187 
[2023-12-12 01:45:39,400] ERROR insert() L140  Erro inesperado ao inserir doador: 'DonatorSchema' object has no attribute 'get' - call_trace=C:\Users\fmsco\OneDrive\Área de Trabalho\Códigos Pós\sprint 2\red_flow\backend\app.py L140 
Traceback (most recent call last):
  File "C:\Users\fmsco\OneDrive\Área de Trabalho\Códigos Pós\sprint 2\red_flow\backend\app.py", line 115, in insert
    outcome=ModelSchema.predicao(modelo, form)
            ^^^^^^^^^^^^^^^^^^^^^^^^^^^^^^^^^^
  File "C:\Users\fmsco\OneDrive\Área de Trabalho\Códigos Pós\sprint 2\red_flow\backend\schemas\donator_schema.py", line 85, in predicao
    outcome_value = form.get('outcome', 0)
                    ^^^^^^^^
AttributeError: 'DonatorSchema' object has no attribute 'get'
[2023-12-12 01:45:39,406] ERROR log_exception() L1414 Exception on /swagger/novodoador [POST] - call_trace=C:\Python311\Lib\site-packages\flask\app.py L1414
Traceback (most recent call last):
  File "C:\Python311\Lib\site-packages\flask\app.py", line 2190, in wsgi_app
    response = self.full_dispatch_request()
               ^^^^^^^^^^^^^^^^^^^^^^^^^^^^
  File "C:\Python311\Lib\site-packages\flask\app.py", line 1487, in full_dispatch_request
    return self.finalize_request(rv)
           ^^^^^^^^^^^^^^^^^^^^^^^^^
  File "C:\Python311\Lib\site-packages\flask\app.py", line 1506, in finalize_request
    response = self.make_response(rv)
               ^^^^^^^^^^^^^^^^^^^^^^
  File "C:\Python311\Lib\site-packages\flask\app.py", line 1820, in make_response
    rv = self.json.response(rv)
         ^^^^^^^^^^^^^^^^^^^^^^
  File "C:\Python311\Lib\site-packages\flask\json\provider.py", line 215, in response
    f"{self.dumps(obj, **dump_args)}\n", mimetype=self.mimetype
       ^^^^^^^^^^^^^^^^^^^^^^^^^^^^
  File "C:\Python311\Lib\site-packages\flask\json\provider.py", line 180, in dumps
    return json.dumps(obj, **kwargs)
           ^^^^^^^^^^^^^^^^^^^^^^^^^
  File "C:\Python311\Lib\json\__init__.py", line 238, in dumps
    **kw).encode(obj)
          ^^^^^^^^^^^
  File "C:\Python311\Lib\json\encoder.py", line 200, in encode
    chunks = self.iterencode(o, _one_shot=True)
             ^^^^^^^^^^^^^^^^^^^^^^^^^^^^^^^^^^
  File "C:\Python311\Lib\json\encoder.py", line 258, in iterencode
    return _iterencode(o, 0)
           ^^^^^^^^^^^^^^^^^
  File "C:\Python311\Lib\site-packages\flask\json\provider.py", line 120, in _default
    raise TypeError(f"Object of type {type(o).__name__} is not JSON serializable")
TypeError: Object of type AttributeError is not JSON serializable
[2023-12-12 01:45:39,410] INFO _log() L187  127.0.0.1 - - [12/Dec/2023 01:45:39] "[35m[1mPOST /swagger/novodoador HTTP/1.1[0m" 500 - - call_trace=C:\Python311\Lib\site-packages\werkzeug\_internal.py L187 
[2023-12-12 01:46:24,856] INFO _log() L187   * Detected change in 'C:\\Users\\fmsco\\OneDrive\\Área de Trabalho\\Códigos Pós\\sprint 2\\red_flow\\backend\\app.py', reloading - call_trace=C:\Python311\Lib\site-packages\werkzeug\_internal.py L187 
[2023-12-12 01:46:24,964] INFO _log() L187   * Restarting with stat - call_trace=C:\Python311\Lib\site-packages\werkzeug\_internal.py L187 
[2023-12-12 01:46:26,954] INFO _log() L187   * Restarting with stat - call_trace=C:\Python311\Lib\site-packages\werkzeug\_internal.py L187 
[2023-12-12 01:46:27,639] INFO _log() L187   * Restarting with stat - call_trace=C:\Python311\Lib\site-packages\werkzeug\_internal.py L187 
[2023-12-12 01:46:31,024] INFO _log() L187   * Detected change in 'C:\\Users\\fmsco\\OneDrive\\Área de Trabalho\\Códigos Pós\\sprint 2\\red_flow\\backend\\app.py', reloading - call_trace=C:\Python311\Lib\site-packages\werkzeug\_internal.py L187 
[2023-12-12 01:46:31,078] INFO _log() L187   * Restarting with stat - call_trace=C:\Python311\Lib\site-packages\werkzeug\_internal.py L187 
[2023-12-12 01:46:32,474] ERROR insert() L140  Erro inesperado ao inserir doador: 'DonatorSchema' object has no attribute 'get' - call_trace=C:\Users\fmsco\OneDrive\Área de Trabalho\Códigos Pós\sprint 2\red_flow\backend\app.py L140 
Traceback (most recent call last):
  File "C:\Users\fmsco\OneDrive\Área de Trabalho\Códigos Pós\sprint 2\red_flow\backend\app.py", line 115, in insert
    outcome=ModelSchema.predicao(modelo, form)
            ^^^^^^^^^^^^^^^^^^^^^^^^^^^^^^^^^^
  File "C:\Users\fmsco\OneDrive\Área de Trabalho\Códigos Pós\sprint 2\red_flow\backend\schemas\donator_schema.py", line 85, in predicao
    outcome_value = form.get('outcome', 0)
                    ^^^^^^^^
AttributeError: 'DonatorSchema' object has no attribute 'get'
[2023-12-12 01:46:32,495] INFO _log() L187  127.0.0.1 - - [12/Dec/2023 01:46:32] "[35m[1mPOST /swagger/novodoador HTTP/1.1[0m" 500 - - call_trace=C:\Python311\Lib\site-packages\werkzeug\_internal.py L187 
[2023-12-12 01:48:44,322] INFO _log() L187   * Detected change in 'C:\\Users\\fmsco\\OneDrive\\Área de Trabalho\\Códigos Pós\\sprint 2\\red_flow\\backend\\app.py', reloading - call_trace=C:\Python311\Lib\site-packages\werkzeug\_internal.py L187 
[2023-12-12 01:50:17,436] INFO _log() L187  [31m[1mWARNING: This is a development server. Do not use it in a production deployment. Use a production WSGI server instead.[0m
 * Running on all addresses (0.0.0.0)
 * Running on http://127.0.0.1:5000
 * Running on http://192.168.15.11:5000 - call_trace=C:\Python311\Lib\site-packages\werkzeug\_internal.py L187 
[2023-12-12 01:50:17,437] INFO _log() L187  [33mPress CTRL+C to quit[0m - call_trace=C:\Python311\Lib\site-packages\werkzeug\_internal.py L187 
[2023-12-12 01:50:17,440] INFO _log() L187   * Restarting with stat - call_trace=C:\Python311\Lib\site-packages\werkzeug\_internal.py L187 
[2023-12-12 01:50:19,536] INFO _log() L187  127.0.0.1 - - [12/Dec/2023 01:50:19] "GET /openapi/swagger HTTP/1.1" 200 - - call_trace=C:\Python311\Lib\site-packages\werkzeug\_internal.py L187 
