[2023-12-12 01:55:58,909] INFO _log() L187  [31m[1mWARNING: This is a development server. Do not use it in a production deployment. Use a production WSGI server instead.[0m
 * Running on all addresses (0.0.0.0)
 * Running on http://127.0.0.1:5000
 * Running on http://192.168.15.11:5000 - call_trace=C:\Python311\Lib\site-packages\werkzeug\_internal.py L187 
[2023-12-12 01:55:58,912] INFO _log() L187  [33mPress CTRL+C to quit[0m - call_trace=C:\Python311\Lib\site-packages\werkzeug\_internal.py L187 
[2023-12-12 01:55:58,915] INFO _log() L187   * Restarting with stat - call_trace=C:\Python311\Lib\site-packages\werkzeug\_internal.py L187 
[2023-12-12 01:56:02,876] ERROR insert() L139  Erro inesperado ao inserir doador: 'Donator' object has no attribute 'dict' - call_trace=C:\Users\fmsco\OneDrive\Área de Trabalho\Códigos Pós\sprint 2\red_flow\backend\app.py L139 
Traceback (most recent call last):
  File "C:\Users\fmsco\OneDrive\Área de Trabalho\Códigos Pós\sprint 2\red_flow\backend\app.py", line 122, in insert
    form_data = DonatorSchema(**doador.dict())
                                ^^^^^^^^^^^
AttributeError: 'Donator' object has no attribute 'dict'
[2023-12-12 01:56:02,879] ERROR log_exception() L1414 Exception on /swagger/novodoador [POST] - call_trace=C:\Python311\Lib\site-packages\flask\app.py L1414
Traceback (most recent call last):
  File "C:\Python311\Lib\site-packages\flask\app.py", line 2190, in wsgi_app
    response = self.full_dispatch_request()
               ^^^^^^^^^^^^^^^^^^^^^^^^^^^^
  File "C:\Python311\Lib\site-packages\flask\app.py", line 1487, in full_dispatch_request
    return self.finalize_request(rv)
           ^^^^^^^^^^^^^^^^^^^^^^^^^
  File "C:\Python311\Lib\site-packages\flask\app.py", line 1506, in finalize_request
    response = self.make_response(rv)
               ^^^^^^^^^^^^^^^^^^^^^^
  File "C:\Python311\Lib\site-packages\flask\app.py", line 1820, in make_response
    rv = self.json.response(rv)
         ^^^^^^^^^^^^^^^^^^^^^^
  File "C:\Python311\Lib\site-packages\flask\json\provider.py", line 215, in response
    f"{self.dumps(obj, **dump_args)}\n", mimetype=self.mimetype
       ^^^^^^^^^^^^^^^^^^^^^^^^^^^^
  File "C:\Python311\Lib\site-packages\flask\json\provider.py", line 180, in dumps
    return json.dumps(obj, **kwargs)
           ^^^^^^^^^^^^^^^^^^^^^^^^^
  File "C:\Python311\Lib\json\__init__.py", line 238, in dumps
    **kw).encode(obj)
          ^^^^^^^^^^^
  File "C:\Python311\Lib\json\encoder.py", line 200, in encode
    chunks = self.iterencode(o, _one_shot=True)
             ^^^^^^^^^^^^^^^^^^^^^^^^^^^^^^^^^^
  File "C:\Python311\Lib\json\encoder.py", line 258, in iterencode
    return _iterencode(o, 0)
           ^^^^^^^^^^^^^^^^^
  File "C:\Python311\Lib\site-packages\flask\json\provider.py", line 120, in _default
    raise TypeError(f"Object of type {type(o).__name__} is not JSON serializable")
TypeError: Object of type AttributeError is not JSON serializable
[2023-12-12 01:56:02,884] INFO _log() L187  127.0.0.1 - - [12/Dec/2023 01:56:02] "[35m[1mPOST /swagger/novodoador HTTP/1.1[0m" 500 - - call_trace=C:\Python311\Lib\site-packages\werkzeug\_internal.py L187 
[2023-12-12 01:56:38,975] INFO _log() L187   * Detected change in 'C:\\Users\\fmsco\\OneDrive\\Área de Trabalho\\Códigos Pós\\sprint 2\\red_flow\\backend\\app.py', reloading - call_trace=C:\Python311\Lib\site-packages\werkzeug\_internal.py L187 
[2023-12-12 01:56:39,085] INFO _log() L187   * Restarting with stat - call_trace=C:\Python311\Lib\site-packages\werkzeug\_internal.py L187 
[2023-12-12 01:56:41,518] INFO _log() L187  127.0.0.1 - - [12/Dec/2023 01:56:41] "POST /swagger/novodoador HTTP/1.1" 200 - - call_trace=C:\Python311\Lib\site-packages\werkzeug\_internal.py L187 
[2023-12-12 01:56:57,454] INFO _log() L187   * Detected change in 'C:\\Users\\fmsco\\OneDrive\\Área de Trabalho\\Códigos Pós\\sprint 2\\red_flow\\backend\\app.py', reloading - call_trace=C:\Python311\Lib\site-packages\werkzeug\_internal.py L187 
[2023-12-12 01:56:57,558] INFO _log() L187   * Restarting with stat - call_trace=C:\Python311\Lib\site-packages\werkzeug\_internal.py L187 
[2023-12-12 01:57:02,219] INFO _log() L187   * Detected change in 'C:\\Users\\fmsco\\OneDrive\\Área de Trabalho\\Códigos Pós\\sprint 2\\red_flow\\backend\\app.py', reloading - call_trace=C:\Python311\Lib\site-packages\werkzeug\_internal.py L187 
[2023-12-12 01:57:02,273] INFO _log() L187   * Restarting with stat - call_trace=C:\Python311\Lib\site-packages\werkzeug\_internal.py L187 
[2023-12-12 01:57:05,105] INFO _log() L187  127.0.0.1 - - [12/Dec/2023 01:57:05] "[35m[1mGET /doador/exibir HTTP/1.1[0m" 202 - - call_trace=C:\Python311\Lib\site-packages\werkzeug\_internal.py L187 
[2023-12-12 01:57:05,369] INFO _log() L187  127.0.0.1 - - [12/Dec/2023 01:57:05] "[35m[1mGET /doador/exibir HTTP/1.1[0m" 202 - - call_trace=C:\Python311\Lib\site-packages\werkzeug\_internal.py L187 
